Workbook
Name Slicer_Year1: #N/A
Name UPDATE: 'Data Sheet'!$E$1

Sheet Profit & Loss
A1: ='Data Sheet'!B1 -> HDFC BANK LTD | H1: =UPDATE | M1: SCREENER.IN
A3: Narration | B3: ='Data Sheet'!B16 -> 42460 | C3: ='Data Sheet'!C16 -> 42825 | D3: ='Data Sheet'!D16 -> 43190 | E3: ='Data Sheet'!E16 -> 43555 | F3: ='Data Sheet'!F16 -> 43921 | G3: ='Data Sheet'!G16 -> 44286 | H3: ='Data Sheet'!H16 -> 44651 | I3: ='Data Sheet'!I16 -> 45016 | ... K3: ='Data Sheet'!K16 -> 45747 | L3: Trailing | M3: Best Case | N3: Worst Case
A4: Sales | B4: ='Data Sheet'!B17 -> 63161.56 | C4: ='Data Sheet'!C17 -> 73271.35 | D4: ='Data Sheet'!D17 -> 85287.84 | E4: ='Data Sheet'!E17 -> 105160.74 | F4: ='Data Sheet'!F17 -> 122189.29 | G4: ='Data Sheet'!G17 -> 128552.4 | H4: ='Data Sheet'!H17 -> 135936.41 | I4: ='Data Sheet'!I17 -> 170754.05 | ... K4: ='Data Sheet'!K17 -> 336367.43 | L4: =SUM(Quarters!H4:K4) -> 348211.99 | M4: =$K4+M23*K4 -> 454960.11 | N4: =$K4+N23*L4 -> 401085.38
A5: Expenses | B5: =SUM('Data Sheet'!B18,'Data Sheet'!B20:B24, -1*'Data Sheet'!B19) -> 20054.62 | C5: =SUM('Data Sheet'!C18,'Data Sheet'!C20:C24, -1*'Data Sheet'!C19) -> 23855.69 | D5: =SUM('Data Sheet'!D18,'Data Sheet'!D20:D24, -1*'Data Sheet'!D19) -> 29532.26 | E5: =SUM('Data Sheet'!E18,'Data Sheet'!E20:E24, -1*'Data Sheet'!E19) -> 34856.27 | F5: =SUM('Data Sheet'!F18,'Data Sheet'!F20:F24, -1*'Data Sheet'!F19) -> 45459.21 | G5: =SUM('Data Sheet'!G18,'Data Sheet'!G20:G24, -1*'Data Sheet'!G19) -> 52456.53 | H5: =SUM('Data Sheet'!H18,'Data Sheet'!H20:H24, -1*'Data Sheet'!H19) -> 56556.96 | I5: =SUM('Data Sheet'!I18,'Data Sheet'!I20:I24, -1*'Data Sheet'!I19) -> 63042.3 | ... K5: =SUM('Data Sheet'!K18,'Data Sheet'!K20:K24, -1*'Data Sheet'!K19) -> 186974.45 | L5: =SUM(Quarters!H5:K5) -> 211511.42 | M5: =M4-M6 -> 244065.34 | N5: =N4-N6 -> 243627.85
A6: Operating Profit | B6: =B4-B5 -> 43106.94 | C6: =C4-C5 -> 49415.66 | D6: =D4-D5 -> 55755.58 | E6: =E4-E5 -> 70304.47 | F6: =F4-F5 -> 76730.08 | G6: =G4-G5 -> 76095.87 | H6: =H4-H5 -> 79379.45 | I6: =I4-I5 -> 107711.75 | ... K6: =K4-K5 -> 149392.98 | L6: =SUM(Quarters!H6:K6) -> 136700.57 | M6: =M4*M24 -> 210894.77 | N6: =N4*N24 -> 157457.53
A7: Other Income | B7: ='Data Sheet'!B25 -> 11211.65 | C7: ='Data Sheet'!C25 -> 12905.08 | D7: ='Data Sheet'!D25 -> 16056.6 | E7: ='Data Sheet'!E25 -> 18947.05 | F7: ='Data Sheet'!F25 -> 24878.97 | G7: ='Data Sheet'!G25 -> 27332.88 | H7: ='Data Sheet'!H25 -> 31758.99 | I7: ='Data Sheet'!I25 -> 33912.05 | ... K7: ='Data Sheet'!K25 -> 134548.5 | L7: =SUM(Quarters!H7:K7) -> 150599.64 | M7: 0 | N7: 0
A8: Depreciation | B8: ='Data Sheet'!B26 -> 738.03 | C8: ='Data Sheet'!C26 -> 886.19 | D8: ='Data Sheet'!D26 -> 966.78 | E8: ='Data Sheet'!E26 -> 1220.67 | F8: ='Data Sheet'!F26 -> 1276.77 | G8: ='Data Sheet'!G26 -> 1385.01 | H8: ='Data Sheet'!H26 -> 1680.73 | I8: ='Data Sheet'!I26 -> 2345.47 | ... K8: ='Data Sheet'!K26 -> 3805.23 | L8: =SUM(Quarters!H8:K8) -> 0 | M8: =+$L8 -> 0 | N8: =+$L8 -> 0
A9: Interest | B9: ='Data Sheet'!B27 -> 34069.57 | C9: ='Data Sheet'!C27 -> 38041.58 | D9: ='Data Sheet'!D27 -> 42381.48 | E9: ='Data Sheet'!E27 -> 53712.69 | F9: ='Data Sheet'!F27 -> 62137.42 | G9: ='Data Sheet'!G27 -> 59247.59 | H9: ='Data Sheet'!H27 -> 58584.33 | I9: ='Data Sheet'!I27 -> 77779.94 | ... K9: ='Data Sheet'!K27 -> 183894.2 | L9: =SUM(Quarters!H9:K9) -> 187257 | M9: =+$L9 -> 187257 | N9: =+$L9 -> 187257
A10: Profit before tax | B10: ='Data Sheet'!B28 -> 19510.99 | C10: ='Data Sheet'!C28 -> 23392.97 | D10: ='Data Sheet'!D28 -> 28463.92 | E10: ='Data Sheet'!E28 -> 34318.16 | F10: ='Data Sheet'!F28 -> 38194.86 | G10: ='Data Sheet'!G28 -> 42796.15 | H10: ='Data Sheet'!H28 -> 50873.38 | I10: ='Data Sheet'!I28 -> 61498.39 | ... K10: ='Data Sheet'!K28 -> 96242.05 | L10: =SUM(Quarters!H10:K10) -> 100043.21 | M10: =M6+M7-SUM(M8:M9) -> 23637.77 | N10: =N6+N7-SUM(N8:N9) -> -29799.47
A11: Tax | B11: ='Data Sheet'!B29 -> 6693.66 | C11: ='Data Sheet'!C29 -> 8078.12 | D11: ='Data Sheet'!D29 -> 9903.08 | E11: ='Data Sheet'!E29 -> 11872.55 | F11: ='Data Sheet'!F29 -> 10898.59 | G11: ='Data Sheet'!G29 -> 10939.38 | H11: ='Data Sheet'!H29 -> 12722.48 | I11: ='Data Sheet'!I29 -> 15349.69 | ... K11: ='Data Sheet'!K29 -> 22801.88 | L11: =SUM(Quarters!H11:K11) -> 22613.4 | M11: =IF($L10>0,$L11/$L10,0) -> 0.22603633 | N11: =IF($L10>0,$L11/$L10,0) -> 0.22603633
A12: Net profit | B12: ='Data Sheet'!B30 -> 12801.33 | C12: ='Data Sheet'!C30 -> 15280.48 | D12: ='Data Sheet'!D30 -> 18510.02 | E12: ='Data Sheet'!E30 -> 22332.43 | F12: ='Data Sheet'!F30 -> 27253.95 | G12: ='Data Sheet'!G30 -> 31833.21 | H12: ='Data Sheet'!H30 -> 38052.75 | I12: ='Data Sheet'!I30 -> 45997.11 | ... K12: ='Data Sheet'!K30 -> 70792.25 | L12: =SUM(Quarters!H12:K12) -> 74510.09 | M12: =M10-M11*M10 -> 18294.775 | N12: =N10-N11*N10 -> -23063.707
A13: EPS | B13: =IF('Data Sheet'!B93>0,B12/'Data Sheet'!B93,0) -> 12.658542 | C13: =IF('Data Sheet'!C93>0,C12/'Data Sheet'!C93,0) -> 14.907494 | D13: =IF('Data Sheet'!D93>0,D12/'Data Sheet'!D93,0) -> 17.831702 | E13: =IF('Data Sheet'!E93>0,E12/'Data Sheet'!E93,0) -> 20.501258 | F13: =IF('Data Sheet'!F93>0,F12/'Data Sheet'!F93,0) -> 24.851777 | G13: =IF('Data Sheet'!G93>0,G12/'Data Sheet'!G93,0) -> 28.872089 | H13: =IF('Data Sheet'!H93>0,H12/'Data Sheet'!H93,0) -> 34.309266 | I13: =IF('Data Sheet'!I93>0,I12/'Data Sheet'!I93,0) -> 41.217895 | ... K13: =IF('Data Sheet'!K93>0,K12/'Data Sheet'!K93,0) -> 46.256142 | L13: =IF('Data Sheet'!$B6>0,'Profit & Loss'!L12/'Data Sheet'!$B6,0) -> 48.420561 | M13: =IF('Data Sheet'!$B6>0,'Profit & Loss'!M12/'Data Sheet'!$B6,0) -> 11.888903 | N13: =IF('Data Sheet'!$B6>0,'Profit & Loss'!N12/'Data Sheet'!$B6,0) -> -14.988006
A14: Price to earning | B14: =IF(B15>0,B15/B13,"") -> 21.154886 | C14: =IF(C15>0,C15/C13,"") -> 24.191859 | D14: =IF(D15>0,D15/D13,"") -> 26.443353 | E14: =IF(E15>0,E15/E13,"") -> 28.277777 | F14: =IF(F15>0,F15/F13,"") -> 17.340812 | G14: =IF(G15>0,G15/G13,"") -> 25.866851 | H14: =IF(H15>0,H15/H13,"") -> 21.428031 | I14: =IF(I15>0,I15/I13,"") -> 19.525015 | ... K14: =IF(K15>0,K15/K13,"") -> 19.7617 | L14: =IF(L13>0,L15/L13,0) -> 15.329232 | M14: =M25 -> 17.946525 | N14: =N25 -> 15.329232
A15: Price | B15: ='Data Sheet'!B90 -> 267.79 | C15: ='Data Sheet'!C90 -> 360.64 | D15: ='Data Sheet'!D90 -> 471.53 | E15: ='Data Sheet'!E90 -> 579.73 | F15: ='Data Sheet'!F90 -> 430.95 | G15: ='Data Sheet'!G90 -> 746.83 | H15: ='Data Sheet'!H90 -> 735.18 | I15: ='Data Sheet'!I90 -> 804.78 | ... K15: ='Data Sheet'!K90 -> 914.1 | L15: ='Data Sheet'!B8 -> 742.25 | M15: =M13*M14 -> 213.36451 | N15: =N13*N14 -> -229.75461
A17: RATIOS:
A18: Dividend Payout | B18: =IF('Data Sheet'!B30>0, 'Data Sheet'!B31/'Data Sheet'!B30, 0) -> 0.18762035 | C18: =IF('Data Sheet'!C30>0, 'Data Sheet'!C31/'Data Sheet'!C30, 0) -> 0.18447064 | D18: =IF('Data Sheet'!D30>0, 'Data Sheet'!D31/'Data Sheet'!D30, 0) -> 0.18225966 | E18: =IF('Data Sheet'!E30>0, 'Data Sheet'!E31/'Data Sheet'!E30, 0) -> 0.18291561 | F18: =IF('Data Sheet'!F30>0, 'Data Sheet'!F31/'Data Sheet'!F30, 0) -> 0.05029803 | G18: =IF('Data Sheet'!G30>0, 'Data Sheet'!G31/'Data Sheet'!G30, 0) -> 0.11256546 | H18: =IF('Data Sheet'!H30>0, 'Data Sheet'!H31/'Data Sheet'!H30, 0) -> 0.22588433 | I18: =IF('Data Sheet'!I30>0, 'Data Sheet'!I31/'Data Sheet'!I30, 0) -> 0.23048035 | ... K18: =IF('Data Sheet'!K30>0, 'Data Sheet'!K31/'Data Sheet'!K30, 0) -> 0.23780626
A19: OPM | B19: =IF(B6>0,B6/B4,0) -> 0.68248694 | C19: =IF(C6>0,C6/C4,0) -> 0.67441995 | D19: =IF(D6>0,D6/D4,0) -> 0.65373423 | E19: =IF(E6>0,E6/E4,0) -> 0.66854294 | F19: =IF(F6>0,F6/F4,0) -> 0.62796076 | G19: =IF(G6>0,G6/G4,0) -> 0.59194437 | H19: =IF(H6>0,H6/H4,0) -> 0.58394546 | I19: =IF(I6>0,I6/I4,0) -> 0.63080056 | ... L19: =IF(L6>0,L6/L4,0) -> 0.39257858
G22: TRENDS: | H22: 10 YEARS | I22: 7 YEARS | J22: 5 YEARS | K22: 3 YEARS | L22: RECENT | M22: BEST | N22: WORST
G23: Sales Growth | H23: =IF(B4=0,"",POWER($K4/B4,1/9)-1) -> 0.20422264 | I23: =IF(D4=0,"",POWER($K4/D4,1/7)-1) -> 0.21655683 | J23: =IF(F4=0,"",POWER($K4/F4,1/5)-1) -> 0.22449258 | K23: =IF(H4=0,"",POWER($K4/H4, 1/3)-1) -> 0.35256885 | L23: =IF(ISERROR(MAX(IF(J4=0,"",(K4-J4)/J4),IF(K4=0,"",(L4-K4)/K4))),"",MAX(IF(J4=0,"",(K4-J4)/J4),IF(K4=0,"",(L4-K4)/K4))) -> 0.1858579 | M23: =MAX(K23:L23) -> 0.35256885 | N23: =MIN(H23:L23) -> 0.1858579
G24: OPM | H24: =IF(SUM(B4:$K$4)=0,"",SUMPRODUCT(B19:$K$19,B4:$K$4)/SUM(B4:$K$4)) -> 0.54332906 | I24: =IF(SUM(E4:$K$4)=0,"",SUMPRODUCT(E19:$K$19,E4:$K$4)/SUM(E4:$K$4)) -> 0.52164604 | J24: =IF(SUM(G4:$K$4)=0,"",SUMPRODUCT(G19:$K$19,G4:$K$4)/SUM(G4:$K$4)) -> 0.49469692 | K24: =IF(SUM(I4:$K$4)=0, "", SUMPRODUCT(I19:$K$19,I4:$K$4)/SUM(I4:$K$4)) -> 0.46354563 | L24: =L19 -> 0.39257858 | M24: =MAX(K24:L24) -> 0.46354563 | N24: =MIN(H24:L24) -> 0.39257858
G25: Price to Earning | H25: =IF(ISERROR(AVERAGEIF(B14:$L14,">0")),"",AVERAGEIF(B14:$L14,">0")) -> 21.499061 | I25: =IF(ISERROR(AVERAGEIF(E14:$L14,">0")),"",AVERAGEIF(E14:$L14,">0")) -> 20.587446 | J25: =IF(ISERROR(AVERAGEIF(G14:$L14,">0")),"",AVERAGEIF(G14:$L14,">0")) -> 19.84683 | K25: =IF(ISERROR(AVERAGEIF(I14:$L14,">0")),"",AVERAGEIF(I14:$L14,">0")) -> 17.946525 | L25: =L14 -> 15.329232 | M25: =MAX(K25:L25) -> 17.946525 | N25: =MIN(H25:L25) -> 15.329232

Sheet KPIs
A2: Revenue and Profit | F2: Balance Sheet | K2: Master Table
A3: Year | B3: Revenue | C3: Profit | E3: Year | F3: Equity | G3: Liability | H3: Asset | J3: Year | K3: Net profit margin | L3: ROE | M3: Debt/equity | N3: Revenue | O3: Profit
A4: ='Profit & Loss'!B3 -> 42460 | B4: =Annual[[#This Row],[Column2]] -> 63161.56 | C4: ='Profit & Loss'!B12 -> 12801.33 | E4: =A4 -> 42460 | F4: ='Balance Sheet'!B4+'Balance Sheet'!B5 -> 74304.13 | G4: ='Balance Sheet'!B6+'Balance Sheet'!B7 -> 687908.2 | H4: =F4+G4 -> 762212.33 | J4: =E4 -> 42460 | K4: =C4/B4 -> 0.20267596 | L4: =C4/F4 -> 0.17228289 | M4: =G4/F4 -> 9.2580076 | N4: =B4 -> 63161.56 | O4: =C4 -> 12801.33
A5: ='Profit & Loss'!C3 -> 42825 | B5: ='Profit & Loss'!C4 -> 73271.35 | C5: ='Profit & Loss'!C12 -> 15280.48 | E5: =A5 -> 42825 | F5: ='Balance Sheet'!C4+'Balance Sheet'!C5 -> 91793.95 | G5: ='Balance Sheet'!C6+'Balance Sheet'!C7 -> 800550.21 | H5: =F5+G5 -> 892344.16 | J5: =E5 -> 42825 | K5: =C5/B5 -> 0.20854645 | L5: =C5/F5 -> 0.166465 | M5: =G5/F5 -> 8.7211653 | N5: =B5 -> 73271.35 | O5: =C5 -> 15280.48
A6: ='Profit & Loss'!D3 -> 43190 | B6: ='Profit & Loss'!D4 -> 85287.84 | C6: ='Profit & Loss'!D12 -> 18510.02 | E6: =A6 -> 43190 | F6: ='Balance Sheet'!D4+'Balance Sheet'!D5 -> 109599.13 | G6: ='Balance Sheet'!D6+'Balance Sheet'!D7 -> 993587.04 | H6: =F6+G6 -> 1103186.2 | J6: =E6 -> 43190 | K6: =C6/B6 -> 0.21703 | L6: =C6/F6 -> 0.16888838 | M6: =G6/F6 -> 9.0656471 | N6: =B6 -> 85287.84 | O6: =C6 -> 18510.02
A7: ='Profit & Loss'!E3 -> 43555 | B7: ='Profit & Loss'!E4 -> 105160.74 | C7: ='Profit & Loss'!E12 -> 22332.43 | E7: =A7 -> 43555 | F7: ='Balance Sheet'!E4+'Balance Sheet'!E5 -> 153672.66 | G7: ='Balance Sheet'!E6+'Balance Sheet'!E7 -> 1139133.1 | H7: =F7+G7 -> 1292805.7 | J7: =E7 -> 43555 | K7: =C7/B7 -> 0.21236471 | L7: =C7/F7 -> 0.14532468 | M7: =G7/F7 -> 7.4127242 | N7: =B7 -> 105160.74 | O7: =C7 -> 22332.43
A8: ='Profit & Loss'!F3 -> 43921 | B8: ='Profit & Loss'!F4 -> 122189.29 | C8: ='Profit & Loss'!F12 -> 27253.95 | E8: =A8 -> 43921 | F8: ='Balance Sheet'!F4+'Balance Sheet'!F5 -> 176358.71 | G8: ='Balance Sheet'!F6+'Balance Sheet'!F7 -> 1404471.7 | H8: =F8+G8 -> 1580830.4 | J8: =E8 -> 43921 | K8: =C8/B8 -> 0.22304696 | L8: =C8/F8 -> 0.15453702 | M8: =G8/F8 -> 7.9637219 | N8: =B8 -> 122189.29 | O8: =C8 -> 27253.95
A9: ='Profit & Loss'!G3 -> 44286 | B9: ='Profit & Loss'!G4 -> 128552.4 | C9: ='Profit & Loss'!G12 -> 31833.21 | E9: =A9 -> 44286 | F9: ='Balance Sheet'!G4+'Balance Sheet'!G5 -> 209810.18 | G9: ='Balance Sheet'!G6+'Balance Sheet'!G7 -> 1589696.5 | H9: =F9+G9 -> 1799506.6 | J9: =E9 -> 44286 | K9: =C9/B9 -> 0.24762828 | L9: =C9/F9 -> 0.15172386 | M9: =G9/F9 -> 7.5768318 | N9: =B9 -> 128552.4 | O9: =C9 -> 31833.21
A10: ='Profit & Loss'!H3 -> 44651 | B10: ='Profit & Loss'!H4 -> 135936.41 | C10: ='Profit & Loss'!H12 -> 38052.75 | E10: =A10 -> 44651 | F10: ='Balance Sheet'!H4+'Balance Sheet'!H5 -> 247326.17 | G10: ='Balance Sheet'!H6+'Balance Sheet'!H7 -> 1875608.1 | H10: =F10+G10 -> 2122934.3 | J10: =E10 -> 44651 | K10: =C10/B10 -> 0.27993052 | L10: =C10/F10 -> 0.15385654 | M10: =G10/F10 -> 7.5835409 | N10: =B10 -> 135936.41 | O10: =C10 -> 38052.75
A11: ='Profit & Loss'!I3 -> 45016 | B11: ='Profit & Loss'!I4 -> 170754.05 | C11: ='Profit & Loss'!I12 -> 45997.11 | E11: =A11 -> 45016 | F11: ='Balance Sheet'!I4+'Balance Sheet'!I5 -> 289437.5 | G11: ='Balance Sheet'!I6+'Balance Sheet'!I7 -> 2240994.9 | H11: =F11+G11 -> 2530432.4 | J11: =E11 -> 45016 | K11: =C11/B11 -> 0.26937639 | L11: =C11/F11 -> 0.15891897 | M11: =G11/F11 -> 7.7425867 | N11: =B11 -> 170754.05 | O11: =C11 -> 45997.11
A12: ='Profit & Loss'!J3 -> 45382 | B12: ='Profit & Loss'!J4 -> 283649.02 | C12: =Annual[[#This Row],[Column10]] -> 64062.04 | E12: =A12 -> 45382 | F12: ='Balance Sheet'!J4+'Balance Sheet'!J5 -> 456395.25 | G12: ='Balance Sheet'!J6+'Balance Sheet'!J7 -> 3573799 | H12: =F12+G12 -> 4030194.3 | J12: =E12 -> 45382 | K12: =C12/B12 -> 0.22584968 | L12: =C12/F12 -> 0.14036526 | M12: =G12/F12 -> 7.8304912 | N12: =B12 -> 283649.02 | O12: =C12 -> 64062.04
A13: ='Profit & Loss'!K3 -> 45747 | B13: ='Profit & Loss'!K4 -> 336367.43 | C13: ='Profit & Loss'!K12 -> 70792.25 | E13: =A13 -> 45747 | F13: ='Balance Sheet'!K4+'Balance Sheet'!K5 -> 521789.39 | G13: ='Balance Sheet'!K6+'Balance Sheet'!K7 -> 3870320.4 | H13: =F13+G13 -> 4392109.8 | J13: =E13 -> 45747 | K13: =C13/B13 -> 0.21046107 | L13: =C13/F13 -> 0.13567208 | M13: =G13/F13 -> 7.4173997 | N13: =B13 -> 336367.43 | O13: =C13 -> 70792.25
B31: Row Labels | C31: Sum of Revenue | E31: Row Labels | F31: Sum of Profit | H31: Row Labels | I31: Sum of ROE | K31: Row Labels | L31: Sum of Net profit margin
B32: 2016 | C32: 63161.56 | E32: 2016 | F32: 12801.33 | H32: 2016 | I32: 0.17228289 | K32: 2016 | L32: 0.20267596
B33: 2017 | C33: 73271.35 | E33: 2017 | F33: 15280.48 | H33: 2017 | I33: 0.166465 | K33: 2017 | L33: 0.20854645
B34: 2018 | C34: 85287.84 | E34: 2018 | F34: 18510.02 | H34: 2018 | I34: 0.16888838 | K34: 2018 | L34: 0.21703
B35: 2019 | C35: 105160.74 | E35: 2019 | F35: 22332.43 | H35: 2019 | I35: 0.14532468 | K35: 2019 | L35: 0.21236471
B36: 2020 | C36: 122189.29 | E36: 2020 | F36: 27253.95 | H36: 2020 | I36: 0.15453702 | K36: 2020 | L36: 0.22304696
B37: 2021 | C37: 128552.4 | E37: 2021 | F37: 31833.21 | H37: 2021 | I37: 0.15172386 | K37: 2021 | L37: 0.24762828
B38: 2022 | C38: 135936.41 | E38: 2022 | F38: 38052.75 | H38: 2022 | I38: 0.15385654 | K38: 2022 | L38: 0.27993052
B39: 2023 | C39: 170754.05 | E39: 2023 | F39: 45997.11 | H39: 2023 | I39: 0.15891897 | K39: 2023 | L39: 0.26937639
B40: 2024 | C40: 283649.02 | E40: 2024 | F40: 64062.04 | H40: 2024 | I40: 0.14036526 | K40: 2024 | L40: 0.22584968
B41: 2025 | C41: 336367.43 | E41: 2025 | F41: 70792.25 | H41: 2025 | I41: 0.13567208 | K41: 2025 | L41: 0.21046107
B42: Grand Total | C42: 1504330.1 | E42: Grand Total | F42: 346915.57 | H42: Grand Total | I42: 1.5480347 | K42: Grand Total | L42: 2.29691
C44: =GETPIVOTDATA("Revenue",$B$31) -> 1504330.1 | F44: =GETPIVOTDATA("Profit",$E$31) -> 346915.57 | I44: =GETPIVOTDATA("ROE",$H$31) -> 1.5480347 | L44: =GETPIVOTDATA("Net profit margin",$K$31) -> 2.29691

Sheet Dashboard
V20: =GETPIVOTDATA("Revenue",KPIs!$A$17) -> #REF!

Sheet DCF
A2: Assumptions
A3: Metrics | B3: Value
A4: Revenue Growth Rate | B4: 0.1
A5: Discounting Rate | B5: 0.12
A6: Forecasting Year | B6: 5
A8: Forecast
A9: Year | B9: Revenue | C9: Net Profit | D9: Cash Flows | E9: Discounted factor | F9: PV of Cash Flows
A10: 2025 | B10: =KPIs!B13 -> 336367.43 | C10: =B10*KPIs!K13 -> 70792.25 | D10: =C10 -> 70792.25 | E10: =1/(1+B5)^1 -> 0.89285714 | F10: =D10*E10 -> 63207.366
A11: 2026 | B11: =B10*(1+B4) -> 370004.17 | C11: =B11*KPIs!K13 -> 77871.475 | D11: =C11 -> 77871.475 | E11: =1/(1+B5)^2 -> 0.79719388 | F11: =D11*E11 -> 62078.663
A12: 2027 | B12: =B11*(1+B4) -> 407004.59 | C12: =B12*KPIs!K13 -> 85658.623 | D12: =C12 -> 85658.623 | E12: =1/(1+B5)^3 -> 0.71178025 | F12: =D12*E12 -> 60970.116
A13: 2028 | B13: =B12*(1+B4) -> 447705.05 | C13: =B13*KPIs!K13 -> 94224.485 | D13: =C13 -> 94224.485 | E13: =1/(1+B5)^4 -> 0.63551808 | F13: =D13*E13 -> 59881.363
A14: 2029 | B14: =B13*(1+B4) -> 492475.55 | C14: =B14*KPIs!K13 -> 103646.93 | D14: =C14 -> 103646.93 | E14: =1/(1+B5)^5 -> 0.56742686 | F14: =D14*E14 -> 58812.053
A15: 2030 | B15: =B14*(1+B4) -> 541723.11 | C15: =B15*KPIs!K13 -> 114011.63 | D15: =C15 -> 114011.63 | E15: =1/(1+B5)^6 -> 0.50663112 | F15: =D15*E15 -> 57761.838
F16: =SUM(F10:F15) -> 362711.4 | G16: =F16*10 -> 3627114
E17: No. of shares | F17: =1538.81 -> 1538.81
A19: Current Price | B19: 742
A20: Intrinsic Value | B20: =G16/F17 -> 2357.0902
A21: Upside/ Downside | B21: =(B20-B19)/B19 -> 2.1766715
A23: Recommendations: | B23: Buy
B24: : Financials are strong and growing.
B25: :Stock is undervalued as per the DCF valuation

Sheet Quarters
A1: ='Profit & Loss'!A1 -> HDFC BANK LTD | E1: =UPDATE | J1: SCREENER.IN
A3: Narration | B3: ='Data Sheet'!B41 -> 45199 | C3: ='Data Sheet'!C41 -> 45291 | D3: ='Data Sheet'!D41 -> 45382 | E3: ='Data Sheet'!E41 -> 45473 | F3: ='Data Sheet'!F41 -> 45565 | G3: ='Data Sheet'!G41 -> 45657 | H3: ='Data Sheet'!H41 -> 45747 | I3: ='Data Sheet'!I41 -> 45838 | ... K3: ='Data Sheet'!K41 -> 46022
A4: Sales | B4: ='Data Sheet'!B42 -> 75039.1 | C4: ='Data Sheet'!C42 -> 78008.17 | D4: ='Data Sheet'!D42 -> 79433.61 | E4: ='Data Sheet'!E42 -> 81546.2 | F4: ='Data Sheet'!F42 -> 83001.72 | G4: ='Data Sheet'!G42 -> 85040.17 | H4: ='Data Sheet'!H42 -> 86779.34 | I4: ='Data Sheet'!I42 -> 87371.87 | ... K4: ='Data Sheet'!K42 -> 87066.94
A5: Expenses | B5: ='Data Sheet'!B43 -> 45349.33 | C5: ='Data Sheet'!C43 -> 50530.03 | D5: ='Data Sheet'!D43 -> 62938.45 | E5: ='Data Sheet'!E43 -> 49689.62 | F5: ='Data Sheet'!F43 -> 52074.11 | G5: ='Data Sheet'!G43 -> 41306.79 | H5: ='Data Sheet'!H43 -> 47709.16 | I5: ='Data Sheet'!I43 -> 64496.63 | ... K5: ='Data Sheet'!K43 -> 54144.75
A6: Operating Profit | B6: ='Data Sheet'!B50 -> 29689.77 | C6: ='Data Sheet'!C50 -> 27478.14 | D6: ='Data Sheet'!D50 -> 16495.16 | E6: ='Data Sheet'!E50 -> 31856.58 | F6: ='Data Sheet'!F50 -> 30927.61 | G6: ='Data Sheet'!G50 -> 43733.38 | H6: ='Data Sheet'!H50 -> 39070.18 | I6: ='Data Sheet'!I50 -> 22875.24 | ... K6: ='Data Sheet'!K50 -> 32922.19
A7: Other Income | B7: ='Data Sheet'!B44 -> 32527.52 | C7: ='Data Sheet'!C44 -> 37007.34 | D7: ='Data Sheet'!D44 -> 44957.74 | E7: ='Data Sheet'!E44 -> 35450.29 | F7: ='Data Sheet'!F44 -> 38455.02 | G7: ='Data Sheet'!G44 -> 27153.77 | H7: ='Data Sheet'!H44 -> 33489.42 | I7: ='Data Sheet'!I44 -> 45683.1 | ... K7: ='Data Sheet'!K44 -> 39860.33
A8: Depreciation | B8: ='Data Sheet'!B45 -> 0 | C8: ='Data Sheet'!C45 -> 0 | D8: ='Data Sheet'!D45 -> 0 | E8: ='Data Sheet'!E45 -> 0 | F8: ='Data Sheet'!F45 -> 0 | G8: ='Data Sheet'!G45 -> 0 | H8: ='Data Sheet'!H45 -> 0 | I8: ='Data Sheet'!I45 -> 0 | ... K8: ='Data Sheet'!K45 -> 0
A9: Interest | B9: ='Data Sheet'!B46 -> 41249.91 | C9: ='Data Sheet'!C46 -> 43242.37 | D9: ='Data Sheet'!D46 -> 43691.51 | E9: ='Data Sheet'!E46 -> 44579.5 | F9: ='Data Sheet'!F46 -> 45414.21 | G9: ='Data Sheet'!G46 -> 46914.28 | H9: ='Data Sheet'!H46 -> 46986.21 | I9: ='Data Sheet'!I46 -> 47708.51 | ... K9: ='Data Sheet'!K46 -> 45821.42
A10: Profit before tax | B10: ='Data Sheet'!B47 -> 20967.38 | C10: ='Data Sheet'!C47 -> 21243.11 | D10: ='Data Sheet'!D47 -> 17761.39 | E10: ='Data Sheet'!E47 -> 22727.37 | F10: ='Data Sheet'!F47 -> 23968.42 | G10: ='Data Sheet'!G47 -> 23972.87 | H10: ='Data Sheet'!H47 -> 25573.39 | I10: ='Data Sheet'!I47 -> 20849.83 | ... K10: ='Data Sheet'!K47 -> 26961.1
A11: Tax | B11: ='Data Sheet'!B48 -> 3655 | C11: ='Data Sheet'!C48 -> 3525.11 | D11: ='Data Sheet'!D48 -> -251.48 | E11: ='Data Sheet'!E48 -> 5539.32 | F11: ='Data Sheet'!F48 -> 5340.98 | G11: ='Data Sheet'!G48 -> 5632.76 | H11: ='Data Sheet'!H48 -> 6288.82 | I11: ='Data Sheet'!I48 -> 3759.4 | ... K11: ='Data Sheet'!K48 -> 6270.06
A12: Net profit | B12: ='Data Sheet'!B49 -> 16811.41 | C12: ='Data Sheet'!C49 -> 17257.87 | D12: ='Data Sheet'!D49 -> 17622.38 | E12: ='Data Sheet'!E49 -> 16474.85 | F12: ='Data Sheet'!F49 -> 17825.91 | G12: ='Data Sheet'!G49 -> 17656.61 | H12: ='Data Sheet'!H49 -> 18834.88 | I12: ='Data Sheet'!I49 -> 16257.91 | ... K12: ='Data Sheet'!K49 -> 19806.63
A14: OPM | B14: =IF(B4>0,B6/B4,"") -> 0.39565733 | C14: =IF(C4>0,C6/C4,"") -> 0.35224695 | D14: =IF(D4>0,D6/D4,"") -> 0.2076597 | E14: =IF(E4>0,E6/E4,"") -> 0.39065683 | F14: =IF(F4>0,F6/F4,"") -> 0.37261409 | G14: =IF(G4>0,G6/G4,"") -> 0.51426732 | H14: =IF(H4>0,H6/H4,"") -> 0.45022444 | I14: =IF(I4>0,I6/I4,"") -> 0.2618147 | ... K14: =IF(K4>0,K6/K4,"") -> 0.37812504

Sheet Balance Sheet
A1: ='Profit & Loss'!A1 -> HDFC BANK LTD | E1: =UPDATE | J1: SCREENER.IN
A3: Narration | B3: ='Data Sheet'!B56 -> 42460 | C3: ='Data Sheet'!C56 -> 42825 | D3: ='Data Sheet'!D56 -> 43190 | E3: ='Data Sheet'!E56 -> 43555 | F3: ='Data Sheet'!F56 -> 43921 | G3: ='Data Sheet'!G56 -> 44286 | H3: ='Data Sheet'!H56 -> 44651 | I3: ='Data Sheet'!I56 -> 45016 | ... K3: ='Data Sheet'!K56 -> 45747
A4: Equity Share Capital | B4: ='Data Sheet'!B57 -> 505.64 | C4: ='Data Sheet'!C57 -> 512.51 | D4: ='Data Sheet'!D57 -> 519.02 | E4: ='Data Sheet'!E57 -> 544.66 | F4: ='Data Sheet'!F57 -> 548.33 | G4: ='Data Sheet'!G57 -> 551.28 | H4: ='Data Sheet'!H57 -> 554.55 | I4: ='Data Sheet'!I57 -> 557.97 | ... K4: ='Data Sheet'!K57 -> 765.22
A5: Reserves | B5: ='Data Sheet'!B58 -> 73798.49 | C5: ='Data Sheet'!C58 -> 91281.44 | D5: ='Data Sheet'!D58 -> 109080.11 | E5: ='Data Sheet'!E58 -> 153128 | F5: ='Data Sheet'!F58 -> 175810.38 | G5: ='Data Sheet'!G58 -> 209258.9 | H5: ='Data Sheet'!H58 -> 246771.62 | I5: ='Data Sheet'!I58 -> 288879.53 | ... K5: ='Data Sheet'!K58 -> 521024.17
A6: Borrowings | B6: ='Data Sheet'!B59 -> 649587.25 | C6: ='Data Sheet'!C59 -> 741549.89 | D6: ='Data Sheet'!D59 -> 944817.22 | E6: ='Data Sheet'!E59 -> 1080235.5 | F6: ='Data Sheet'!F59 -> 1333041.4 | G6: ='Data Sheet'!G59 -> 1511417.6 | H6: ='Data Sheet'!H59 -> 1784969.5 | I6: ='Data Sheet'!I59 -> 2139211.9 | ... K6: ='Data Sheet'!K59 -> 3345503.8
A7: Other Liabilities | B7: ='Data Sheet'!B60 -> 38320.95 | C7: ='Data Sheet'!C60 -> 59000.32 | D7: ='Data Sheet'!D60 -> 48769.82 | E7: ='Data Sheet'!E60 -> 58897.59 | F7: ='Data Sheet'!F60 -> 71430.27 | G7: ='Data Sheet'!G60 -> 78278.83 | H7: ='Data Sheet'!H60 -> 90638.6 | I7: ='Data Sheet'!I60 -> 101783.03 | ... K7: ='Data Sheet'!K60 -> 524816.64
A8: Total | B8: ='Data Sheet'!B61 -> 762212.33 | C8: ='Data Sheet'!C61 -> 892344.16 | D8: ='Data Sheet'!D61 -> 1103186.2 | E8: ='Data Sheet'!E61 -> 1292805.7 | F8: ='Data Sheet'!F61 -> 1580830.4 | G8: ='Data Sheet'!G61 -> 1799506.6 | H8: ='Data Sheet'!H61 -> 2122934.3 | I8: ='Data Sheet'!I61 -> 2530432.4 | ... K8: ='Data Sheet'!K61 -> 4392109.8
A10: Net Block | B10: ='Data Sheet'!B62 -> 3666.86 | C10: ='Data Sheet'!C62 -> 3999.7 | D10: ='Data Sheet'!D62 -> 4008.13 | E10: ='Data Sheet'!E62 -> 4368.63 | F10: ='Data Sheet'!F62 -> 4775.65 | G10: ='Data Sheet'!G62 -> 5248.35 | H10: ='Data Sheet'!H62 -> 6432.07 | I10: ='Data Sheet'!I62 -> 8431.35 | ... K10: ='Data Sheet'!K62 -> 15257.94
A11: Capital Work in Progress | B11: ='Data Sheet'!B63 -> 0 | C11: ='Data Sheet'!C63 -> 0 | D11: ='Data Sheet'!D63 -> 0 | E11: ='Data Sheet'!E63 -> 0 | F11: ='Data Sheet'!F63 -> 0 | G11: ='Data Sheet'!G63 -> 0 | H11: ='Data Sheet'!H63 -> 0 | I11: ='Data Sheet'!I63 -> 0 | ... K11: ='Data Sheet'!K63 -> 0
A12: Investments | B12: ='Data Sheet'!B64 -> 193633.85 | C12: ='Data Sheet'!C64 -> 210777.11 | D12: ='Data Sheet'!D64 -> 238460.92 | E12: ='Data Sheet'!E64 -> 289445.87 | F12: ='Data Sheet'!F64 -> 389304.95 | G12: ='Data Sheet'!G64 -> 438823.11 | H12: ='Data Sheet'!H64 -> 449263.86 | I12: ='Data Sheet'!I64 -> 511581.71 | ... K12: ='Data Sheet'!K64 -> 1186472.9
A13: Other Assets | B13: ='Data Sheet'!B65 -> 564911.62 | C13: ='Data Sheet'!C65 -> 677567.35 | D13: ='Data Sheet'!D65 -> 860717.12 | E13: ='Data Sheet'!E65 -> 998991.21 | F13: ='Data Sheet'!F65 -> 1186749.8 | G13: ='Data Sheet'!G65 -> 1355435.2 | H13: ='Data Sheet'!H65 -> 1667238.4 | I13: ='Data Sheet'!I65 -> 2010419.4 | ... K13: ='Data Sheet'!K65 -> 3190379
A14: Total | B14: ='Data Sheet'!B66 -> 762212.33 | C14: ='Data Sheet'!C66 -> 892344.16 | D14: ='Data Sheet'!D66 -> 1103186.2 | E14: ='Data Sheet'!E66 -> 1292805.7 | F14: ='Data Sheet'!F66 -> 1580830.4 | G14: ='Data Sheet'!G66 -> 1799506.6 | H14: ='Data Sheet'!H66 -> 2122934.3 | I14: ='Data Sheet'!I66 -> 2530432.4 | ... K14: ='Data Sheet'!K66 -> 4392109.8
A16: Working Capital | B16: =B13-B7 -> 526590.67 | C16: =C13-C7 -> 618567.03 | D16: =D13-D7 -> 811947.3 | E16: =E13-E7 -> 940093.62 | F16: =F13-F7 -> 1115319.6 | G16: =G13-G7 -> 1277156.3 | H16: =H13-H7 -> 1576599.8 | I16: =I13-I7 -> 1908636.3 | ... K16: =K13-K7 -> 2665562.4
A17: Debtors | B17: ='Data Sheet'!B67 -> 0 | C17: ='Data Sheet'!C67 -> 0 | D17: ='Data Sheet'!D67 -> 0 | E17: ='Data Sheet'!E67 -> 0 | F17: ='Data Sheet'!F67 -> 0 | G17: ='Data Sheet'!G67 -> 0 | H17: ='Data Sheet'!H67 -> 0 | I17: ='Data Sheet'!I67 -> 0 | ... K17: ='Data Sheet'!K67 -> 0
A18: Inventory | B18: ='Data Sheet'!B68 -> 0 | C18: ='Data Sheet'!C68 -> 0 | D18: ='Data Sheet'!D68 -> 0 | E18: ='Data Sheet'!E68 -> 0 | F18: ='Data Sheet'!F68 -> 0 | G18: ='Data Sheet'!G68 -> 0 | H18: ='Data Sheet'!H68 -> 0 | I18: ='Data Sheet'!I68 -> 0 | ... K18: ='Data Sheet'!K68 -> 0
A20: Debtor Days | B20: =IF('Profit & Loss'!B4>0,'Balance Sheet'!B17/('Profit & Loss'!B4/365),0) -> 0 | C20: =IF('Profit & Loss'!C4>0,'Balance Sheet'!C17/('Profit & Loss'!C4/365),0) -> 0 | D20: =IF('Profit & Loss'!D4>0,'Balance Sheet'!D17/('Profit & Loss'!D4/365),0) -> 0 | E20: =IF('Profit & Loss'!E4>0,'Balance Sheet'!E17/('Profit & Loss'!E4/365),0) -> 0 | F20: =IF('Profit & Loss'!F4>0,'Balance Sheet'!F17/('Profit & Loss'!F4/365),0) -> 0 | G20: =IF('Profit & Loss'!G4>0,'Balance Sheet'!G17/('Profit & Loss'!G4/365),0) -> 0 | H20: =IF('Profit & Loss'!H4>0,'Balance Sheet'!H17/('Profit & Loss'!H4/365),0) -> 0 | I20: =IF('Profit & Loss'!I4>0,'Balance Sheet'!I17/('Profit & Loss'!I4/365),0) -> 0 | ... K20: =IF('Profit & Loss'!K4>0,'Balance Sheet'!K17/('Profit & Loss'!K4/365),0) -> 0
A21: Inventory Turnover | B21: =IF('Balance Sheet'!B18>0,'Profit & Loss'!B4/'Balance Sheet'!B18,0) -> 0 | C21: =IF('Balance Sheet'!C18>0,'Profit & Loss'!C4/'Balance Sheet'!C18,0) -> 0 | D21: =IF('Balance Sheet'!D18>0,'Profit & Loss'!D4/'Balance Sheet'!D18,0) -> 0 | E21: =IF('Balance Sheet'!E18>0,'Profit & Loss'!E4/'Balance Sheet'!E18,0) -> 0 | F21: =IF('Balance Sheet'!F18>0,'Profit & Loss'!F4/'Balance Sheet'!F18,0) -> 0 | G21: =IF('Balance Sheet'!G18>0,'Profit & Loss'!G4/'Balance Sheet'!G18,0) -> 0 | H21: =IF('Balance Sheet'!H18>0,'Profit & Loss'!H4/'Balance Sheet'!H18,0) -> 0 | I21: =IF('Balance Sheet'!I18>0,'Profit & Loss'!I4/'Balance Sheet'!I18,0) -> 0 | ... K21: =IF('Balance Sheet'!K18>0,'Profit & Loss'!K4/'Balance Sheet'!K18,0) -> 0
A23: Return on Equity | B23: =IF(SUM('Balance Sheet'!B4:B5)>0,'Profit & Loss'!B12/SUM('Balance Sheet'!B4:B5),"") -> 0.17228289 | C23: =IF(SUM('Balance Sheet'!C4:C5)>0,'Profit & Loss'!C12/SUM('Balance Sheet'!C4:C5),"") -> 0.166465 | D23: =IF(SUM('Balance Sheet'!D4:D5)>0,'Profit & Loss'!D12/SUM('Balance Sheet'!D4:D5),"") -> 0.16888838 | E23: =IF(SUM('Balance Sheet'!E4:E5)>0,'Profit & Loss'!E12/SUM('Balance Sheet'!E4:E5),"") -> 0.14532468 | F23: =IF(SUM('Balance Sheet'!F4:F5)>0,'Profit & Loss'!F12/SUM('Balance Sheet'!F4:F5),"") -> 0.15453702 | G23: =IF(SUM('Balance Sheet'!G4:G5)>0,'Profit & Loss'!G12/SUM('Balance Sheet'!G4:G5),"") -> 0.15172386 | H23: =IF(SUM('Balance Sheet'!H4:H5)>0,'Profit & Loss'!H12/SUM('Balance Sheet'!H4:H5),"") -> 0.15385654 | I23: =IF(SUM('Balance Sheet'!I4:I5)>0,'Profit & Loss'!I12/SUM('Balance Sheet'!I4:I5),"") -> 0.15891897 | ... K23: =IF(SUM('Balance Sheet'!K4:K5)>0,'Profit & Loss'!K12/SUM('Balance Sheet'!K4:K5),"") -> 0.13567208
A24: Return on Capital Emp | C24: =IF((B4+B5+B6+C4+C5+C6)>0,('Profit & Loss'!C10+'Profit & Loss'!C9)*2/(B4+B5+B6+C4+C5+C6),"") -> 0.078902081 | D24: =IF((C4+C5+C6+D4+D5+D6)>0,('Profit & Loss'!D10+'Profit & Loss'!D9)*2/(C4+C5+C6+D4+D5+D6),"") -> 0.075057627 | E24: =IF((D4+D5+D6+E4+E5+E6)>0,('Profit & Loss'!E10+'Profit & Loss'!E9)*2/(D4+D5+D6+E4+E5+E6),"") -> 0.076939133 | F24: =IF((E4+E5+E6+F4+F5+F6)>0,('Profit & Loss'!F10+'Profit & Loss'!F9)*2/(E4+E5+E6+F4+F5+F6),"") -> 0.073146923 | G24: =IF((F4+F5+F6+G4+G5+G6)>0,('Profit & Loss'!G10+'Profit & Loss'!G9)*2/(F4+F5+F6+G4+G5+G6),"") -> 0.063172697 | H24: =IF((G4+G5+G6+H4+H5+H6)>0,('Profit & Loss'!H10+'Profit & Loss'!H9)*2/(G4+G5+G6+H4+H5+H6),"") -> 0.058322645 | I24: =IF((H4+H5+H6+I4+I5+I6)>0,('Profit & Loss'!I10+'Profit & Loss'!I9)*2/(H4+H5+H6+I4+I5+I6),"") -> 0.062443418 | J24: =IF((I4+I5+I6+J4+J5+J6)>0,('Profit & Loss'!J10+'Profit & Loss'!J9)*2/(I4+I5+I6+J4+J5+J6),"") -> 0.076998023 | K24: =IF((J4+J5+J6+K4+K5+K6)>0,('Profit & Loss'!K10+'Profit & Loss'!K9)*2/(J4+J5+J6+K4+K5+K6),"") -> 0.075394709

Sheet Cash Flow
A1: ='Balance Sheet'!A1 -> HDFC BANK LTD | E1: =UPDATE | J1: SCREENER.IN
A3: Narration | B3: ='Data Sheet'!B81 -> 42460 | C3: ='Data Sheet'!C81 -> 42825 | D3: ='Data Sheet'!D81 -> 43190 | E3: ='Data Sheet'!E81 -> 43555 | F3: ='Data Sheet'!F81 -> 43921 | G3: ='Data Sheet'!G81 -> 44286 | H3: ='Data Sheet'!H81 -> 44651 | I3: ='Data Sheet'!I81 -> 45016 | ... K3: ='Data Sheet'!K81 -> 45747
A4: Cash from Operating Activity | B4: ='Data Sheet'!B82 -> -34435.37 | C4: ='Data Sheet'!C82 -> 17281.59 | D4: ='Data Sheet'!D82 -> 17214.38 | E4: ='Data Sheet'!E82 -> -62871.54 | F4: ='Data Sheet'!F82 -> -16869.09 | G4: ='Data Sheet'!G82 -> 42476.45 | H4: ='Data Sheet'!H82 -> -11959.57 | I4: ='Data Sheet'!I82 -> 20813.7 | ... K4: ='Data Sheet'!K82 -> 127241.84
A5: Cash from Investing Activity | B5: ='Data Sheet'!B83 -> -837.31 | C5: ='Data Sheet'!C83 -> -1146.38 | D5: ='Data Sheet'!D83 -> -841.6 | E5: ='Data Sheet'!E83 -> -1503.06 | F5: ='Data Sheet'!F83 -> -1402.94 | G5: ='Data Sheet'!G83 -> -1822.7 | H5: ='Data Sheet'!H83 -> -2051.23 | I5: ='Data Sheet'!I83 -> -2992.18 | ... K5: ='Data Sheet'!K83 -> -3650.91
A6: Cash from Financing Activity | B6: ='Data Sheet'!B84 -> 37815.13 | C6: ='Data Sheet'!C84 -> -5892.97 | D6: ='Data Sheet'!D84 -> 57377.66 | E6: ='Data Sheet'!E84 -> 23130.69 | F6: ='Data Sheet'!F84 -> 24394.5 | G6: ='Data Sheet'!G84 -> -7321.35 | H6: ='Data Sheet'!H84 -> 48124.02 | I6: ='Data Sheet'!I84 -> 23940.56 | ... K6: ='Data Sheet'!K84 -> -102477.54
A7: Net Cash Flow | B7: ='Data Sheet'!B85 -> 2542.46 | C7: ='Data Sheet'!C85 -> 10242.24 | D7: ='Data Sheet'!D85 -> 73750.44 | E7: ='Data Sheet'!E85 -> -41243.91 | F7: ='Data Sheet'!F85 -> 6122.47 | G7: ='Data Sheet'!G85 -> 33332.4 | H7: ='Data Sheet'!H85 -> 34113.22 | I7: ='Data Sheet'!I85 -> 41762.08 | ... K7: ='Data Sheet'!K85 -> 21113.39

Sheet Customization
A1: How to use it?
A3: You can customize this workbook as you want.
B4: You can add custom formating, add conditional formating, add your own formulas… do ANYTHING.
B5: Please don't edit the "Data Sheet" only.
A7: After customization, you can upload this back on Screener.
B8: Upload on: | C8: https://www.screener.in/excel/
A10: Download your customized workbooks now onwards.
B11: Now whenever you will "Export to excel" from Screener, it will export your customized file.
A14: TESTING:
B15: This is a testing feature currently.
B16: You can report any formula errors on the worksheet at: support@screener.in

Sheet Data Sheet
A1: COMPANY NAME | B1: HDFC BANK LTD | E1: =IF(B2<>B3, "A NEW VERSION OF THE WORKSHEET IS AVAILABLE", "")
A2: LATEST VERSION | B2: 2.1 | E2: PLEASE DO NOT MAKE ANY CHANGES TO THIS SHEET
A3: CURRENT VERSION | B3: 2.1
A5: META
A6: Number of shares | B6: =IF(B9>0, B9/B8, 0) -> 1538.811
A7: Face Value | B7: 1
A8: Current Price | B8: 742.25
A9: Market Capitalization | B9: 1142182.4
A15: PROFIT & LOSS
A16: Report Date | B16: 42460 | C16: 42825 | D16: 43190 | E16: 43555 | F16: 43921 | G16: 44286 | H16: 44651 | I16: 45016 | J16: 45382 | K16: 45747
A17: Sales | B17: 63161.56 | C17: 73271.35 | D17: 85287.84 | E17: 105160.74 | F17: 122189.29 | G17: 128552.4 | H17: 135936.41 | I17: 170754.05 | J17: 283649.02 | K17: 336367.43
A18: Raw Material Cost
A19: Change in Inventory
A20: Power and Fuel
A21: Other Mfr. Exp | B21: 1041.79 | C21: 1271.8 | D21: 1314.97 | E21: 1283.53 | F21: 1293.44 | G21: 1649.11 | H21: 1772.27 | I21: 2176.5 | J21: 3255.75 | K21: 3943.56
A22: Employee Cost | B22: 6309.03 | C22: 8508.22 | D22: 9197.15 | E22: 10454.75 | F22: 12924.1 | G22: 13682.35 | H22: 15904.81 | I22: 20031.36 | J22: 31050.07 | K22: 34167.89
A23: Selling and admin | B23: 3043.15 | C23: 3328.39 | D23: 3658.43 | E23: 3900.17 | F23: 4192.15 | G23: 4780.54 | H23: 5406.79 | I23: 6580 | J23: 87580.05 | K23: 105188.45
A24: Other Expenses | B24: 9660.65 | C24: 10747.28 | D24: 15361.71 | E24: 19217.82 | F24: 27049.52 | G24: 32344.53 | H24: 33473.09 | I24: 34254.44 | J24: 52309.67 | K24: 43674.55
A25: Other Income | B25: 11211.65 | C25: 12905.08 | D25: 16056.6 | E25: 18947.05 | F25: 24878.97 | G25: 27332.88 | H25: 31758.99 | I25: 33912.05 | J25: 124345.75 | K25: 134548.5
A26: Depreciation | B26: 738.03 | C26: 886.19 | D26: 966.78 | E26: 1220.67 | F26: 1276.77 | G26: 1385.01 | H26: 1680.73 | I26: 2345.47 | J26: 3092.08 | K26: 3805.23
A27: Interest | B27: 34069.57 | C27: 38041.58 | D27: 42381.48 | E27: 53712.69 | F27: 62137.42 | G27: 59247.59 | H27: 58584.33 | I27: 77779.94 | J27: 154138.55 | K27: 183894.2
A28: Profit before tax | B28: 19510.99 | C28: 23392.97 | D28: 28463.92 | E28: 34318.16 | F28: 38194.86 | G28: 42796.15 | H28: 50873.38 | I28: 61498.39 | J28: 76568.6 | K28: 96242.05
A29: Tax | B29: 6693.66 | C29: 8078.12 | D29: 9903.08 | E29: 11872.55 | F29: 10898.59 | G29: 10939.38 | H29: 12722.48 | I29: 15349.69 | J29: 11122.1 | K29: 22801.88
A30: Net profit | B30: 12801.33 | C30: 15280.48 | D30: 18510.02 | E30: 22332.43 | F30: 27253.95 | G30: 31833.21 | H30: 38052.75 | I30: 45997.11 | J30: 64062.04 | K30: 70792.25
A31: Dividend Amount | B31: 2401.79 | C31: 2818.8 | D31: 3373.63 | E31: 4084.95 | F31: 1370.82 | G31: 3583.32 | H31: 8595.52 | I31: 10601.43 | J31: 14813.96 | K31: 16834.84
A40: Quarters
A41: Report Date | B41: 45199 | C41: 45291 | D41: 45382 | E41: 45473 | F41: 45565 | G41: 45657 | H41: 45747 | I41: 45838 | J41: 45930 | K41: 46022
A42: Sales | B42: 75039.1 | C42: 78008.17 | D42: 79433.61 | E42: 81546.2 | F42: 83001.72 | G42: 85040.17 | H42: 86779.34 | I42: 87371.87 | J42: 86993.84 | K42: 87066.94
A43: Expenses | B43: 45349.33 | C43: 50530.03 | D43: 62938.45 | E43: 49689.62 | F43: 52074.11 | G43: 41306.79 | H43: 47709.16 | I43: 64496.63 | J43: 45160.88 | K43: 54144.75
A44: Other Income | B44: 32527.52 | C44: 37007.34 | D44: 44957.74 | E44: 35450.29 | F44: 38455.02 | G44: 27153.77 | H44: 33489.42 | I44: 45683.1 | J44: 31566.79 | K44: 39860.33
A45: Depreciation
A46: Interest | B46: 41249.91 | C46: 43242.37 | D46: 43691.51 | E46: 44579.5 | F46: 45414.21 | G46: 46914.28 | H46: 46986.21 | I46: 47708.51 | J46: 46740.86 | K46: 45821.42
A47: Profit before tax | B47: 20967.38 | C47: 21243.11 | D47: 17761.39 | E47: 22727.37 | F47: 23968.42 | G47: 23972.87 | H47: 25573.39 | I47: 20849.83 | J47: 26658.89 | K47: 26961.1
A48: Tax | B48: 3655 | C48: 3525.11 | D48: -251.48 | E48: 5539.32 | F48: 5340.98 | G48: 5632.76 | H48: 6288.82 | I48: 3759.4 | J48: 6295.12 | K48: 6270.06
A49: Net profit | B49: 16811.41 | C49: 17257.87 | D49: 17622.38 | E49: 16474.85 | F49: 17825.91 | G49: 17656.61 | H49: 18834.88 | I49: 16257.91 | J49: 19610.67 | K49: 19806.63
A50: Operating Profit | B50: 29689.77 | C50: 27478.14 | D50: 16495.16 | E50: 31856.58 | F50: 30927.61 | G50: 43733.38 | H50: 39070.18 | I50: 22875.24 | J50: 41832.96 | K50: 32922.19
A55: BALANCE SHEET
A56: Report Date | B56: 42460 | C56: 42825 | D56: 43190 | E56: 43555 | F56: 43921 | G56: 44286 | H56: 44651 | I56: 45016 | J56: 45382 | K56: 45747
A57: Equity Share Capital | B57: 505.64 | C57: 512.51 | D57: 519.02 | E57: 544.66 | F57: 548.33 | G57: 551.28 | H57: 554.55 | I57: 557.97 | J57: 759.69 | K57: 765.22
A58: Reserves | B58: 73798.49 | C58: 91281.44 | D58: 109080.11 | E58: 153128 | F58: 175810.38 | G58: 209258.9 | H58: 246771.62 | I58: 288879.53 | J58: 455635.56 | K58: 521024.17
...
